<?xml version="1.0" encoding="UTF-8"?>
<testng-results skipped="0" failed="1" ignored="0" total="4" passed="3">
  <reporter-output>
    <line>
      <![CDATA[[INFO] : Assertion Passed : Add New Entry functionality is working fine]]>
    </line>
    <line>
      <![CDATA[[INFO] : Assertion Passed : Able to read collection]]>
    </line>
    <line>
      <![CDATA[[INFO] : Assertion Passed : Able to remove entry from collection]]>
    </line>
  </reporter-output>
  <suite name="Default suite" duration-ms="63" started-at="2018-07-09T08:29:24Z" finished-at="2018-07-09T08:29:24Z">
    <groups>
    </groups>
    <test name="Default test" duration-ms="63" started-at="2018-07-09T08:29:24Z" finished-at="2018-07-09T08:29:24Z">
      <class name="testquestion2.Test_MyCollection">
        <test-method status="PASS" signature="Test1_Able_To_Add_New_Entry_In_Collection()[pri:0, instance:testquestion2.Test_MyCollection@1810399e]" name="Test1_Able_To_Add_New_Entry_In_Collection" duration-ms="15" started-at="2018-07-09T08:29:24Z" description="Check Add functionality" finished-at="2018-07-09T08:29:24Z">
          <reporter-output>
            <line>
              <![CDATA[[INFO] : Assertion Passed : Add New Entry functionality is working fine]]>
            </line>
          </reporter-output>
        </test-method> <!-- Test1_Able_To_Add_New_Entry_In_Collection -->
        <test-method status="PASS" signature="Test3_Get_Collection_Functionality()[pri:0, instance:testquestion2.Test_MyCollection@1810399e]" name="Test3_Get_Collection_Functionality" duration-ms="16" started-at="2018-07-09T08:29:24Z" description="Check toString function" finished-at="2018-07-09T08:29:24Z">
          <reporter-output>
            <line>
              <![CDATA[[INFO] : Assertion Passed : Able to read collection]]>
            </line>
          </reporter-output>
        </test-method> <!-- Test3_Get_Collection_Functionality -->
        <test-method status="FAIL" signature="Test4_DoubleCapacity()[pri:0, instance:testquestion2.Test_MyCollection@1810399e]" name="Test4_DoubleCapacity" duration-ms="0" started-at="2018-07-09T08:29:24Z" description="Check Overflow Collection" finished-at="2018-07-09T08:29:24Z">
          <exception class="java.lang.AssertionError">
            <message>
              <![CDATA[Assertion Failed : Not able to add number in collection once it get fulled expected [{4,5,-4,-5,6}] but found [{Automation, Testing, Is, AlwaysA Fun}]]]>
            </message>
            <full-stacktrace>
              <![CDATA[java.lang.AssertionError: Assertion Failed : Not able to add number in collection once it get fulled expected [{4,5,-4,-5,6}] but found [{Automation, Testing, Is, AlwaysA Fun}]
at org.testng.Assert.fail(Assert.java:96)
at org.testng.Assert.failNotEquals(Assert.java:776)
at org.testng.Assert.assertEqualsImpl(Assert.java:137)
at org.testng.Assert.assertEquals(Assert.java:118)
at org.testng.Assert.assertEquals(Assert.java:453)
at testquestion2.Test_MyCollection.Test4_DoubleCapacity(Test_MyCollection.java:41)
at sun.reflect.NativeMethodAccessorImpl.invoke0(Native Method)
at sun.reflect.NativeMethodAccessorImpl.invoke(Unknown Source)
at sun.reflect.DelegatingMethodAccessorImpl.invoke(Unknown Source)
at java.lang.reflect.Method.invoke(Unknown Source)
at org.testng.internal.MethodInvocationHelper.invokeMethod(MethodInvocationHelper.java:124)
at org.testng.internal.Invoker.invokeMethod(Invoker.java:583)
at org.testng.internal.Invoker.invokeTestMethod(Invoker.java:719)
at org.testng.internal.Invoker.invokeTestMethods(Invoker.java:989)
at org.testng.internal.TestMethodWorker.invokeTestMethods(TestMethodWorker.java:125)
at org.testng.internal.TestMethodWorker.run(TestMethodWorker.java:109)
at org.testng.TestRunner.privateRun(TestRunner.java:648)
at org.testng.TestRunner.run(TestRunner.java:505)
at org.testng.SuiteRunner.runTest(SuiteRunner.java:455)
at org.testng.SuiteRunner.runSequentially(SuiteRunner.java:450)
at org.testng.SuiteRunner.privateRun(SuiteRunner.java:415)
at org.testng.SuiteRunner.run(SuiteRunner.java:364)
at org.testng.SuiteRunnerWorker.runSuite(SuiteRunnerWorker.java:52)
at org.testng.SuiteRunnerWorker.run(SuiteRunnerWorker.java:84)
at org.testng.TestNG.runSuitesSequentially(TestNG.java:1208)
at org.testng.TestNG.runSuitesLocally(TestNG.java:1137)
at org.testng.TestNG.runSuites(TestNG.java:1049)
at org.testng.TestNG.run(TestNG.java:1017)
at org.testng.remote.AbstractRemoteTestNG.run(AbstractRemoteTestNG.java:114)
at org.testng.remote.RemoteTestNG.initAndRun(RemoteTestNG.java:251)
at org.testng.remote.RemoteTestNG.main(RemoteTestNG.java:77)
]]>
            </full-stacktrace>
          </exception> <!-- java.lang.AssertionError -->
          <reporter-output>
          </reporter-output>
        </test-method> <!-- Test4_DoubleCapacity -->
        <test-method status="PASS" signature="Test5_Remove_Functionality_If_Entry_Already_Present()[pri:0, instance:testquestion2.Test_MyCollection@1810399e]" name="Test5_Remove_Functionality_If_Entry_Already_Present" duration-ms="0" started-at="2018-07-09T08:29:24Z" description="Check remove functionality" finished-at="2018-07-09T08:29:24Z">
          <reporter-output>
            <line>
              <![CDATA[[INFO] : Assertion Passed : Able to remove entry from collection]]>
            </line>
          </reporter-output>
        </test-method> <!-- Test5_Remove_Functionality_If_Entry_Already_Present -->
      </class> <!-- testquestion2.Test_MyCollection -->
    </test> <!-- Default test -->
  </suite> <!-- Default suite -->
</testng-results>
